Starting training...
Epochs:   0%|          | 0/600 [00:00<?, ?it/s]
Training:   0%|          | 0/9 [00:00<?, ?it/s]
Traceback (most recent call last):
  File "/home/mgornet/Bureau/Code/CNPEN/train.py", line 187, in <module>
    model = training(model, device, optimizer, scheduler, criterion, epochs, train_loader, valid_loader, save_epoch=False)
  File "/home/mgornet/Bureau/Code/CNPEN/files/test_train_loops.py", line 98, in training
    for step, (anchor_img, positive_img, negative_img) \
  File "/home/mgornet/anaconda3/envs/face_reco/lib/python3.9/site-packages/tqdm/notebook.py", line 257, in __iter__
    for obj in super(tqdm_notebook, self).__iter__():
  File "/home/mgornet/anaconda3/envs/face_reco/lib/python3.9/site-packages/tqdm/std.py", line 1195, in __iter__
    for obj in iterable:
  File "/home/mgornet/anaconda3/envs/face_reco/lib/python3.9/site-packages/torch/utils/data/dataloader.py", line 530, in __next__
    data = self._next_data()
  File "/home/mgornet/anaconda3/envs/face_reco/lib/python3.9/site-packages/torch/utils/data/dataloader.py", line 1224, in _next_data
    return self._process_data(data)
  File "/home/mgornet/anaconda3/envs/face_reco/lib/python3.9/site-packages/torch/utils/data/dataloader.py", line 1250, in _process_data
    data.reraise()
  File "/home/mgornet/anaconda3/envs/face_reco/lib/python3.9/site-packages/torch/_utils.py", line 457, in reraise
    raise exception
AttributeError: Caught AttributeError in DataLoader worker process 0.
Original Traceback (most recent call last):
  File "/home/mgornet/anaconda3/envs/face_reco/lib/python3.9/site-packages/torch/utils/data/_utils/worker.py", line 287, in _worker_loop
    data = fetcher.fetch(index)
  File "/home/mgornet/anaconda3/envs/face_reco/lib/python3.9/site-packages/torch/utils/data/_utils/fetch.py", line 51, in fetch
    data = self.dataset[possibly_batched_index]
  File "/home/mgornet/Bureau/Code/CNPEN/files/triplet.py", line 425, in __getitem__
    imgs_a = self.Xa[low_index:high_index]  # Anchors
  File "/home/mgornet/anaconda3/envs/face_reco/lib/python3.9/site-packages/torch/nn/modules/module.py", line 1185, in __getattr__
    raise AttributeError("'{}' object has no attribute '{}'".format(
AttributeError: 'RandomTripletGenerator' object has no attribute 'Xa'